Workbook

Sheet Cover
B2: Moncler S.p.A (BIT: MONC) - Strategic Expansion Into Luxury Leather Goods
B3: Date: June 2026 - Prepared by Lorenzo Grimaldi
B4: This document is an academic simulation prepared for portfolio purposes only, prepared under academic supervision. It does not constitute investment advice or a recommendation to buy or sell securities.
B5: Identification and evaluation of potential acquisition targets to strengthen Moncler's exposure to the luxury leather goods segment. | D5: Financial data: S&P Global Capital IQ and Company Filings Valuation assumptions: Damodaran Online, management guidance and analyst consensus estimates Historical financial statements: Company Annual Reports and Stock Analysis.
B6: Market Screening & Long - List Analysis
B7: Financial Screening
B8: Company | C8: Market Cap (€M) | D8: EV (€M) | E8: EV/EBITDA | F8: Gross Margin | G8: Revenue FY 2025 (€M) | H8: Revenue Growth
B9: Salvatore Ferragamo S.p.A (BIT: SFER) | C9: 1620 | D9: 2070 | E9: 18,24x | F9: 0.681 | G9: 976.53 | H9: -0.0566
B10: Ermenegildo Zegna (NYSE: ZGN) | C10: 3520 | D10: 4330 | E10: 15,04x | F10: 0.6751 | G10: 1917 | H10: -0.0153
B11: Brunello Culcinelli S.p.A. (BIT: BC) | C11: 5600 | D11: 6600 | E11: 15,79x | F11: 0.5406 | G11: 1408 | H11: 0.1012
B12: Capri Holdings Limited (NYSE: CPRI) | C12: 2210 | D12: 3490 | E12: 17,54x | F12: 0.6226 | G12: 3621 | H12: -0.1254
B13: Aeffe S.p.A. (BIT: AEF) | C13: 17.81 | D13: 189.06 | E13: 10,38x | F13: 0.0147 | G13: 232.89 | H13: -0.2306
B14: Piquadro S.p.A. (BIT: PQ) | C14: 129.15 | D14: 168.17 | E14: 10,51x | F14: 0.4096 | G14: 184.32 | H14: -0.013
B15: Lanvin Group Holdings Limited (NYSE: LANV) | C15: 184.77 | D15: 735.93 | E15: (4)x | F15: 0.5816 | G15: 240.5 | H15: -0.176
B16: Burberry Group plc | C16: 3830 | D16: 4690 | E16: 9,53x | F16: 0.6789 | G16: 2420 | H16: -0.0167
B17: Mulberry Group plc (AIM: MUL) | C17: 95.42 | D17: 148.08 | E17: (10)x | F17: 0.6807 | G17: 120.39 | H17: -0.2123
B18: Moncler S.p.A. | C18: 13820 | D18: 13490 | E18: 11,13x | F18: 0.781 | G18: 3132 | H18: 0.0075
B19: Industry Average | E19: 15,23x | F19: 0.6504
B21: Strategic Fit
B22: Company | C22: Leather Goods Exposure | D22: Seasonalibility Complement | E22: Brand Positioning | F22: Acquisition Feasibility | G22: Governance Risk | H22: Valuation Score | I22: Overall Fit
B23: Salvatore Ferragamo S.p.A (BIT: SFER) | C23: 4 | D23: 5 | E23: 4 | F23: {=_xlfn.IFS(D9/$D$18<0.1,5,D9/$D$18<0.2,4,D9/$D$18<0.35,3,D9/$D$18<0.5,2, TRUE, 1)} -> 4 | G23: 4 | H23: 5 | I23: =0.25*(C23)+0.15*(D23)+0.2*(E23)+0.15*(F23)+0.1*(G23)+0.15*(H23) -> 4.3 | J23: =IF(I23>3.5, "Recommend", "Not recommend") -> Recommend
B24: Ermenegildo Zegna (NYSE: ZGN) | C24: 3 | D24: 2 | E24: 4 | F24: {=_xlfn.IFS(D10/$D$18<0.2,5,D10/$D$18<0.3,4,D10/$D$18<0.5,3,D10/$D$18<0.6,2, TRUE, 1)} -> 3 | G24: 4 | H24: 4 | I24: =0.25*(C24)+0.15*(D24)+0.2*(E24)+0.15*(F24)+0.1*(G24)+0.15*(H24) -> 3.3 | J24: =IF(I24>3.5, "Recommend", "Not recommend") -> Not recommend
B25: Brunello Culcinelli S.p.A. (BIT: BC) | C25: 1 | D25: 2 | E25: 5 | F25: {=_xlfn.IFS(D11/$D$18<0.2,5,D11/$D$18<0.3,4,D11/$D$18<0.5,3,D11/$D$18<0.6,2, TRUE, 1)} -> 3 | G25: 1 | H25: 4 | I25: =0.25*(C25)+0.15*(D25)+0.2*(E25)+0.15*(F25)+0.1*(G25)+0.15*(H25) -> 2.7 | J25: =IF(I25>3.5, "Recommend", "Not recommend") -> Not recommend
B26: Capri Holdings Limited (NYSE: CPRI) | C26: 4 | D26: 2 | E26: 2 | F26: {=_xlfn.IFS(D12/$D$18<0.2,5,D12/$D$18<0.3,4,D12/$D$18<0.5,3,D12/$D$18<0.6,2, TRUE, 1)} -> 4 | G26: 4 | H26: 5 | I26: =0.25*(C26)+0.15*(D26)+0.2*(E26)+0.15*(F26)+0.1*(G26)+0.15*(H26) -> 3.45 | J26: =IF(I26>3.5, "Recommend", "Not recommend") -> Not recommend
B27: Aeffe S.p.A. (BIT: AEF) | C27: 2 | D27: 3 | E27: 3 | F27: {=_xlfn.IFS(D13/$D$18<0.2,5,D13/$D$18<0.3,4,D13/$D$18<0.5,3,D13/$D$18<0.6,2, TRUE, 1)} -> 5 | G27: 2 | H27: 3 | I27: =0.25*(C27)+0.15*(D27)+0.2*(E27)+0.15*(F27)+0.1*(G27)+0.15*(H27) -> 2.95 | J27: =IF(I27>3.5, "Recommend", "Not recommend") -> Not recommend
B28: Piquadro S.p.A. (BIT: PQ) | C28: 5 | D28: 4 | E28: 3 | F28: {=_xlfn.IFS(D14/$D$18<0.2,5,D14/$D$18<0.3,4,D14/$D$18<0.5,3,D14/$D$18<0.6,2, TRUE, 1)} -> 5 | G28: 1 | H28: 3 | I28: =0.25*(C28)+0.15*(D28)+0.2*(E28)+0.15*(F28)+0.1*(G28)+0.15*(H28) -> 3.75 | J28: =IF(I28>3.5, "Recommend", "Not recommend") -> Recommend
B29: Lanvin Group Holdings Limited (NYSE: LANV) | C29: 2 | D29: 4 | E29: 4 | F29: {=_xlfn.IFS(D15/$D$18<0.2,5,D15/$D$18<0.3,4,D15/$D$18<0.5,3,D15/$D$18<0.6,2, TRUE, 1)} -> 5 | G29: 4 | H29: 1 | I29: =0.25*(C29)+0.15*(D29)+0.2*(E29)+0.15*(F29)+0.1*(G29)+0.15*(H29) -> 3.2 | J29: =IF(I29>3.5, "Recommend", "Not recommend") -> Not recommend
B30: Burberry Group plc | C30: 4 | D30: 4 | E30: 5 | F30: {=_xlfn.IFS(D16/$D$18<0.2,5,D16/$D$18<0.3,4,D16/$D$18<0.5,3,D16/$D$18<0.6,2, TRUE, 1)} -> 3 | G30: 3 | H30: 2 | I30: =0.25*(C30)+0.15*(D30)+0.2*(E30)+0.15*(F30)+0.1*(G30)+0.15*(H30) -> 3.65 | J30: =IF(I30>3.5, "Recommend", "Not recommend") -> Recommend
B31: Mulberry Group plc (AIM: MUL) | C31: 5 | D31: 4 | E31: 3 | F31: {=_xlfn.IFS(D17/$D$18<0.2,5,D17/$D$18<0.3,4,D17/$D$18<0.5,3,D17/$D$18<0.6,2, TRUE, 1)} -> 5 | G31: 4 | H31: 1 | I31: =0.25*(C31)+0.15*(D31)+0.2*(E31)+0.15*(F31)+0.1*(G31)+0.15*(H31) -> 3.75 | J31: =IF(I31>3.5, "Recommend", "Not recommend") -> Recommend

Sheet Short List
B2: Moncler S.p.A. - Short List
B4: Short List
B5: Company
B6: Salvatore Ferragamo S.p.A. | C6: Recommend
B7: Piquadro S.p.A. | C7: Not recommend | D7: Despite passing the quantitative screening, Piquadro is eliminated at the short list stage due to structural acquisition barriers. The founder-led ownership structure and absence of any public indication of willingness to engage in M&A discussions suggest a prolonged negotiation process and a materially higher acquisition premium relative to peers, reducing the risk-adjusted return of the transaction.
B8: Burberry Group plc | C8: Recommend
B9: Mulberry Group plc | C9: Recommend

Sheet DCF - Ferragamo
B2: Salvatore Ferragamo S.p.A. - DCF Valuation
B4: Valuation Date | C4: June 2026
B5: Current Share Price | C5: 10.27
B6: Number of public share (€M) | C6: 165.68
B8: Select Operating Data
G9: Projected Annual Forecast
C10: FY2023 | D10: FY2024 | E10: FY2025 | F10: FY2026 | G10: FY2027 | H10: FY2028 | I10: FY2029 | J10: FY2030
B11: Revenue | C11: 1156 | D11: 1035 | E11: 976.53 | F11: =E11*(1+F12) -> 988.24836 | G11: =F11*(1+G12) -> 1003.0721 | H11: =G11*(1+H12) -> 1023.1335 | I11: =H11*(1+I12) -> 1051.7813 | J11: =I11*(1+J12) -> 1088.5936
B12: Revenue Growth Rate (%) | F12: 0.012 | G12: 0.015 | H12: 0.02 | I12: 0.028 | J12: 0.035
B15: EBITDA | C15: 119.21 | D15: -7.79 | E15: 17.01 | F15: =F11*F16 -> 88.942352 | G15: =G11*G16 -> 95.291848 | H15: =H11*H16 -> 104.35962 | I15: =I11*I16 -> 114.64416 | J15: =J11*J16 -> 125.18827
B16: EBITDA Margin | C16: =C15/C11 -> 0.10312284 | D16: =D15/D11 -> -0.00752657 | E16: =E15/E11 -> 0.01741882 | F16: 0.09 | G16: 0.095 | H16: 0.102 | I16: 0.109 | J16: 0.115
B19: EBIT | C19: 78.38 | D19: -51.01 | E19: -20.25 | F19: =F15-F22 -> -138.9341 | G19: =G15-G22 -> -136.00276 | H19: =H15-H22 -> -131.56088 | I19: =I15-I22 -> -127.88211 | J19: =J15-J22 -> -125.82642
B20: EBIT Margin (%) | C20: =C19/C11 -> 0.067802768 | D20: =D19/D11 -> -0.049285024 | E20: =E19/E11 -> -0.02073669 | F20: =F19/F11 -> -0.14058622 | G20: =G19/G11 -> -0.13558622 | H20: =H19/H11 -> -0.12858622 | I20: =I19/I11 -> -0.12158622 | J20: =J19/J11 -> -0.11558622
B22: Depreciation & Amortization | C22: 283.1 | D22: 264.2 | E22: 187.1 | F22: =F11*F23 -> 227.87646 | G22: =G11*G23 -> 231.2946 | H22: =H11*H23 -> 235.9205 | I22: =I11*I23 -> 242.52627 | J22: =J11*J23 -> 251.01469
B23: D&A as a % of Revenue | C23: =C22/C11 -> 0.24489619 | D23: =D22/D11 -> 0.2552657 | E23: =E22/E11 -> 0.19159678 | F23: =AVERAGE($C$23:$E$23) -> 0.23058622 | G23: =AVERAGE($C$23:$E$23) -> 0.23058622 | H23: =AVERAGE($C$23:$E$23) -> 0.23058622 | I23: =AVERAGE($C$23:$E$23) -> 0.23058622 | J23: =AVERAGE($C$23:$E$23) -> 0.23058622
B24: Select Balance Sheet & Other Data
G25: Projected Annual Forecast
C26: FY2023 | D26: FY2024 | E26: FY2025 | F26: FY2026 | G26: FY2027 | H26: FY2028 | I26: FY2029 | J26: FY2030
B27: Cash | C27: 268.99 | D27: 238.19 | E27: 207.44
B28: Accounts Recevable | C28: 122.43 | D28: 84.58 | E28: 59.43 | F28: =F40*F11 -> 81.855444 | G28: =G40*G11 -> 83.083276 | H28: =H40*H11 -> 84.744942 | I28: =I40*I11 -> 87.1178 | J28: =J40*J11 -> 90.166923
B29: Inventories | C29: 298.35 | D29: 307.89 | E29: 278.63 | F29: =F11*F41 -> 277.00375 | G29: =G11*G41 -> 281.1588 | H29: =H11*H41 -> 286.78198 | I29: =I11*I41 -> 294.81187 | J29: =J11*J41 -> 305.13029
B30: Prepaid Expenses | C30: 7.3 | D30: 7.62 | E30: 8.06 | F30: =F42*F11 -> 7.2243961 | G30: =G42*G11 -> 7.332762 | H30: =H42*H11 -> 7.4794173 | I30: =I42*I11 -> 7.6888409 | J30: =J42*J11 -> 7.9579504
B32: Accounts Payable | C32: 172 | D32: 162.8 | E32: 123.53 | F32: =F43*F11 -> 142.49966 | G32: =G43*G11 -> 144.63716 | H32: =H43*H11 -> 147.5299 | I32: =I43*I11 -> 151.66074 | J32: =J43*J11 -> 156.96886
B33: Accrued Expenses | C33: 33.5 | D33: 28.04 | E33: 21.83 | F33: =F44*F11 -> 25.834687 | G33: =G44*G11 -> 26.222207 | H33: =H44*H11 -> 26.746651 | I33: =I44*I11 -> 27.495557 | J33: =J44*J11 -> 28.457902
B35: Debt | C35: 121.6 | D35: 113.3 | E35: 104.3
B36: Interest Expenses | C36: 5.3 | D36: 4.7 | E36: 3.6
B38: Gross PP&E (Increases annually be capex) | C38: 817.3 | D38: 734.19 | E38: 635.26
B40: Accounts Recevable % of revenue | C40: =C28/C11 -> 0.1059083 | D40: =D28/D11 -> 0.081719807 | E40: =E28/E11 -> 0.060858345 | F40: =AVERAGE($C$40:$E$40) -> 0.082828819 | G40: =AVERAGE($C$40:$E$40) -> 0.082828819 | H40: =AVERAGE($C$40:$E$40) -> 0.082828819 | I40: =AVERAGE($C$40:$E$40) -> 0.082828819 | J40: =AVERAGE($C$40:$E$40) -> 0.082828819
B41: Inventories % of revenue | C41: =C29/C11 -> 0.25808824 | D41: =D29/D11 -> 0.29747826 | E41: =E29/E11 -> 0.28532662 | F41: =AVERAGE($C$41:$E$41) -> 0.2802977 | G41: =AVERAGE($C$41:$E$41) -> 0.2802977 | H41: =AVERAGE($C$41:$E$41) -> 0.2802977 | I41: =AVERAGE($C$41:$E$41) -> 0.2802977 | J41: =AVERAGE($C$41:$E$41) -> 0.2802977
B42: Prepaid Expenses % of revenue | C42: =C30/C11 -> 0.0063148789 | D42: =D30/D11 -> 0.0073623188 | E42: =E30/E11 -> 0.0082537147 | F42: =AVERAGE($C$42:$E$42) -> 0.0073103041 | G42: =AVERAGE($C$42:$E$42) -> 0.0073103041 | H42: =AVERAGE($C$42:$E$42) -> 0.0073103041 | I42: =AVERAGE($C$42:$E$42) -> 0.0073103041 | J42: =AVERAGE($C$42:$E$42) -> 0.0073103041
B43: Accounts Payable % of revenue | C43: =C32/C11 -> 0.14878893 | D43: =D32/D11 -> 0.15729469 | E43: =E32/E11 -> 0.12649893 | F43: =AVERAGE($C$43:$E$43) -> 0.14419418 | G43: =AVERAGE($C$43:$E$43) -> 0.14419418 | H43: =AVERAGE($C$43:$E$43) -> 0.14419418 | I43: =AVERAGE($C$43:$E$43) -> 0.14419418 | J43: =AVERAGE($C$43:$E$43) -> 0.14419418
B44: Accrued Expenses % of revenue | C44: =C33/C11 -> 0.028979239 | D44: =D33/D11 -> 0.027091787 | E44: =E33/E11 -> 0.022354664 | F44: =AVERAGE($C$44:$E$44) -> 0.026141897 | G44: =AVERAGE($C$44:$E$44) -> 0.026141897 | H44: =AVERAGE($C$44:$E$44) -> 0.026141897 | I44: =AVERAGE($C$44:$E$44) -> 0.026141897 | J44: =AVERAGE($C$44:$E$44) -> 0.026141897
B45: Capital Expenditures % of revenue | C45: =C81/C11 -> -0.050250865 | D45: =D81/D11 -> -0.059236715 | E45: =E81/E11 -> -0.040531269 | F45: =AVERAGE($C$45:$E$45) -> -0.050006283 | G45: =AVERAGE($C$45:$E$45) -> -0.050006283 | H45: =AVERAGE($C$45:$E$45) -> -0.050006283 | I45: =AVERAGE($C$45:$E$45) -> -0.050006283 | J45: =AVERAGE($C$45:$E$45) -> -0.050006283
B47: WACC
B48: Share Price | D48: =C5 -> 10.27
B49: Dilueted Shares Outstanding | D49: 165.2
B50: Cost of debt | D50: =AVERAGE(C36:E36)/AVERAGE(C35:E35) -> 0.04009434
B51: Tax rate | D51: 0.24
B52: After tax cost of debt | D52: =D50*(1-D51) -> 0.030471698
B53: Beta Levered | D53: =0.74*(1+(1-D51)*(D55/D56)) -> 0.77620884
...

Sheet DCF - Burberry
B2: Burberry Group plc - DCF Valuation
B4: Valuation Date | C4: June 2026
B5: Current Share Price | C5: =11.12*1.14 -> 12.6768
B6: Number of public share (M) | C6: 358.21
B8: Select Operating Data
G9: Projected Annual Forecast
C10: FY2023 | D10: FY2024 | E10: FY2025 | F10: FY2026 | G10: FY2027 | H10: FY2028 | I10: FY2029 | J10: FY2030
B11: Revenue | C11: =3094*1.16 -> 3589.04 | D11: =2968*1.16 -> 3442.88 | E11: =2461*1.16 -> 2854.76 | F11: =E11*(1+F12) -> 2806.2291 | G11: =F11*(1+G12) -> 2820.2602 | H11: =G11*(1+H12) -> 2876.6654 | I11: =H11*(1+I12) -> 2957.2121 | J11: =I11*(1+J12) -> 3051.8428
B12: Revenue Growth Rate (%) | F12: -0.017 | G12: 0.005 | H12: 0.02 | I12: 0.028 | J12: 0.032
B15: EBITDA | C15: =1001*1.16 -> 1161.16 | D15: =797*1.16 -> 924.52 | E15: =410*1.16 -> 475.6 | F15: =F11*F16 -> 448.99665 | G15: =G11*G16 -> 473.80372 | H15: =H11*H16 -> 494.78645 | I15: =I11*I16 -> 532.29817 | J15: =J11*J16 -> 564.59093
B16: EBITDA Margin | C16: =C15/C11 -> 0.32352941 | D16: =D15/D11 -> 0.268531 | E16: =E15/E11 -> 0.16659894 | F16: 0.16 | G16: 0.168 | H16: 0.172 | I16: 0.18 | J16: 0.185
B19: EBIT | C19: =657*1.16 -> 762.12 | D19: =418*1.16 -> 484.88 | E19: =-3*1.16 -> -3.48 | F19: =F15-F22 -> 68.56898 | G19: =G15-G22 -> 91.473906 | H19: =H15-H22 -> 104.81005 | I19: =I15-I22 -> 131.40242 | J19: =J15-J22 -> 150.86652
B20: EBIT Margin (%) | C20: =C19/C11 -> 0.21234648 | D20: =D19/D11 -> 0.14083558 | F20: =F19/F11 -> 0.024434562 | G20: =G19/G11 -> 0.032434562 | H20: =H19/H11 -> 0.036434562 | I20: =I19/I11 -> 0.044434562 | J20: =J19/J11 -> 0.049434562
B22: Depreciation & Amortization | C22: =344*1.16 -> 399.04 | D22: =379*1.16 -> 439.64 | E22: =413*1.16 -> 479.08 | F22: =F11*F23 -> 380.42767 | G22: =G11*G23 -> 382.32981 | H22: =H11*H23 -> 389.97641 | I22: =I11*I23 -> 400.89575 | J22: =J11*J23 -> 413.72441
B23: D&A as a % of Revenue | C23: =C22/C11 -> 0.11118293 | D23: =D22/D11 -> 0.12769542 | E23: =E22/E11 -> 0.16781796 | F23: =AVERAGE($C$23:$E$23) -> 0.13556544 | G23: =AVERAGE($C$23:$E$23) -> 0.13556544 | H23: =AVERAGE($C$23:$E$23) -> 0.13556544 | I23: =AVERAGE($C$23:$E$23) -> 0.13556544 | J23: =AVERAGE($C$23:$E$23) -> 0.13556544
B25: Select Balance Sheet & Other Data
G26: Projected Annual Forecast
C27: FY2023 | D27: FY2024 | E27: FY2025 | F27: FY2026 | G27: FY2027 | H27: FY2028 | I27: FY2029 | J27: FY2030
B28: Cash | C28: =1026*1.16 -> 1190.16 | D28: =441*1.16 -> 511.56 | E28: =813*1.16 -> 943.08
B29: Accounts Recevable | C29: =307*1.16 -> 356.12 | D29: =340*1.16 -> 394.4 | E29: =309*1.16 -> 358.44 | F29: =F11*F41 -> 317.42031 | G29: =G11*G41 -> 319.00742 | H29: =H11*H41 -> 325.38756 | I29: =I11*I41 -> 334.49842 | J29: =J11*J41 -> 345.20236
B30: Inventories | C30: =447*1.16 -> 518.52 | D30: =507*1.16 -> 588.12 | E30: =424*1.16 -> 491.84 | F30: =F11*F42 -> 456.08983 | G30: =G11*G42 -> 458.37028 | H30: =H11*H42 -> 467.53769 | I30: =I11*I42 -> 480.62874 | J30: =J11*J42 -> 496.00886
B31: Prepaid Expenses
B33: Accounts Payable | C33: =477*1.16 -> 553.32 | D33: =439*1.16 -> 509.24 | E33: =405*1.16 -> 469.8 | F33: =F11*F43 -> 436.50674 | G33: =G11*G43 -> 438.68928 | H33: =H11*H43 -> 447.46306 | I33: =I11*I43 -> 459.99203 | J33: =J11*J43 -> 474.71177
B34: Accrued Expenses
B36: Debt | C36: 363 | D36: 378 | E36: 843
C37: 42 | D37: 66 | E37: 88
B39: Gross PP&E (Increases annually be capex) | C39: =1326*1.16 -> 1538.16 | D39: =1419*1.16 -> 1646.04 | E39: =1265*1.16 -> 1467.4
B41: Accounts Recevable % of revenue | C41: =C29/C11 -> 0.099224305 | D41: =D29/D11 -> 0.11455526 | E41: =E29/E11 -> 0.12555872 | F41: =AVERAGE($C$41:$E$41) -> 0.11311276 | G41: =AVERAGE($C$41:$E$41) -> 0.11311276 | H41: =AVERAGE($C$41:$E$41) -> 0.11311276 | I41: =AVERAGE($C$41:$E$41) -> 0.11311276 | J41: =AVERAGE($C$41:$E$41) -> 0.11311276
B42: Inventories % revenue | C42: =C30/C11 -> 0.14447317 | D42: =D30/D11 -> 0.1708221 | E42: =E30/E11 -> 0.17228769 | F42: =AVERAGE($C$42:$E$42) -> 0.16252765 | G42: =AVERAGE($C$42:$E$42) -> 0.16252765 | H42: =AVERAGE($C$42:$E$42) -> 0.16252765 | I42: =AVERAGE($C$42:$E$42) -> 0.16252765 | J42: =AVERAGE($C$42:$E$42) -> 0.16252765
B43: Accounts Payable % of revenue | C43: =C33/C11 -> 0.15416936 | D43: =D33/D11 -> 0.14791105 | E43: =E33/E11 -> 0.16456725 | F43: =AVERAGE($C$43:$E$43) -> 0.15554922 | G43: =AVERAGE($C$43:$E$43) -> 0.15554922 | H43: =AVERAGE($C$43:$E$43) -> 0.15554922 | I43: =AVERAGE($C$43:$E$43) -> 0.15554922 | J43: =AVERAGE($C$43:$E$43) -> 0.15554922
B44: Capital Expenditures % of revenue | C44: =C81/C11 -> -0.05106658 | D44: =D81/D11 -> -0.041105121 | E44: =E81/E11 -> -0.0292564 | F44: =AVERAGE($C$44:$E$44) -> -0.040476034 | G44: =AVERAGE($C$44:$E$44) -> -0.040476034 | H44: =AVERAGE($C$44:$E$44) -> -0.040476034 | I44: =AVERAGE($C$44:$E$44) -> -0.040476034 | J44: =AVERAGE($C$44:$E$44) -> -0.040476034
B46: WACC
B47: Share Price | D47: =C5 -> 12.6768
B48: Dilueted Shares Outstanding | D48: 358.21
B49: Cost of debt | D49: =AVERAGE(C37:E37)/AVERAGE(C36:E36) -> 0.12373737
B50: Tax rate | D50: 0.25
B51: After tax cost of debt | D51: =D49*(1-D50) -> 0.09280303
B52: Beta Levered | D52: =0.74*(1+(1-D50)*(D55/D56)) -> 0.80453266
B53: Cost of equity | D53: =(4.74+5*D52) -> 8.7626633
B55: Total debt | D55: =AVERAGE(C36:E36) -> 528
...

Sheet DCF - Mulberry Group plc
B2: Mulberry Group plc - DCF Valuation
B4: Valuation Date | C4: June 2026
B5: Current Share Price | C5: =1.4*1.14 -> 1.596
B6: Number of public share (M) | C6: 70.16
B8: Select Operating Data
G9: Projected Annual Forecast
C10: FY2023 | D10: FY2024 | E10: FY2025 | F10: FY2026 | G10: FY2027 | H10: FY2028 | I10: FY2029 | J10: FY2030
B11: Revenue | C11: 184.6 | D11: 177.3 | E11: 120.4 | F11: =E11*(1+F12) -> 123.41 | G11: =F11*(1+G12) -> 126.49525 | H11: =G11*(1+H12) -> 129.65763 | I11: =H11*(1+I12) -> 132.89907 | J11: =I11*(1+J12) -> 136.22155
B12: Revenue Growth Rate (%) | F12: 0.025 | G12: 0.025 | H12: 0.025 | I12: 0.025 | J12: 0.025
B15: EBITDA | C15: =11.88*1.16 -> 13.7808 | D15: =-14.33*1.16 -> -16.6228 | E15: =-22.06*1.16 -> -25.5896 | F15: =F11*F16 -> 4.31935 | G15: =G11*G16 -> 5.05981 | H15: =H11*H16 -> 5.8345934 | I15: =I11*I16 -> 6.6449536 | J15: =J11*J16 -> 8.1732929
B16: EBITDA Margin | C16: =C15/C11 -> 0.074652221 | D16: =D15/D11 -> -0.093755217 | E16: =E15/E11 -> -0.21253821 | F16: 0.035 | G16: 0.04 | H16: 0.045 | I16: 0.05 | J16: 0.06
B19: EBIT | C19: =5.18*1.16 -> 6.0088 | D19: =-19.28*1.16 -> -22.3648 | E19: =-26.3*1.16 -> -30.508 | F19: =F15-F22 -> -10.442686 | G19: =G15-G22 -> -11.162997 | H19: =H15-H22 -> -11.993534 | I19: =I15-I22 -> -12.947347 | J19: =J15-J22 -> -13.357755
B20: EBIT Margin (%) | C20: =C19/C11 -> 0.032550379 | D20: =D19/D11 -> -0.126141 | E20: =E19/E11 -> -0.2533887 | F20: =F19/F11 -> -0.08461783 | G20: =G19/G11 -> -0.088248348 | H20: =H19/H11 -> -0.092501564 | I20: =I19/I11 -> -0.097422407 | J20: =J19/J11 -> -0.098059046
B22: Depreciation & Amortization | C22: =14.63*1.16 -> 16.9708 | D22: =14.27*1.16 -> 16.5532 | E22: =11.58*1.16 -> 13.4328 | F22: =E22*(1+F23) -> 14.762036 | G22: =F22*(1+G23) -> 16.222807 | H22: =G22*(1+H23) -> 17.828127 | I22: =H22*(1+I23) -> 19.592301 | J22: =I22*(1+J23) -> 21.531048
B23: D&A as a % of Revenue | C23: =C22/C11 -> 0.091932828 | D23: =D22/D11 -> 0.093362662 | E23: =E22/E11 -> 0.11156811 | F23: =AVERAGE($C$23:$E$23) -> 0.098954532 | G23: =AVERAGE($C$23:$E$23) -> 0.098954532 | H23: =AVERAGE($C$23:$E$23) -> 0.098954532 | I23: =AVERAGE($C$23:$E$23) -> 0.098954532 | J23: =AVERAGE($C$23:$E$23) -> 0.098954532
B24: Select Balance Sheet & Other Data
G25: Projected Annual Forecast
C26: FY2023 | D26: FY2024 | E26: FY2025 | F26: FY2026 | G26: FY2027 | H26: FY2028 | I26: FY2029 | J26: FY2030
B27: Cash | C27: =6.87*1.16 -> 7.9692 | D27: =7.14*1.16 -> 8.2824 | E27: =8.2*1.16 -> 9.512
B28: Accounts Recevable | C28: =7.39*1.16 -> 8.5724 | D28: =4.72*1.16 -> 5.4752 | E28: =3.15*1.16 -> 3.654 | F28: =F11*F40 -> 4.4290834 | G28: =G11*G40 -> 4.5398105 | H28: =H11*H40 -> 4.6533058 | I28: =I11*I40 -> 4.7696384 | J28: =J11*J40 -> 4.8888794
B29: Inventories | C29: =48.25*1.16 -> 55.97 | D29: =33.16*1.16 -> 38.4656 | E29: =18.22*1.16 -> 21.1352 | F29: =F41*F11 -> 28.618355 | G29: =G41*G11 -> 29.333814 | H29: =H41*H11 -> 30.067159 | I29: =I41*I11 -> 30.818838 | J29: =J41*J11 -> 31.589309
B30: Prepaid Expenses | C30: =7.08*1.16 -> 8.2128 | D30: =7.3*1.16 -> 8.468 | E30: =6.19*1.16 -> 7.1804 | F30: =F42*F11 -> 6.2481841 | G30: =G42*G11 -> 6.4043887 | H30: =H42*H11 -> 6.5644984 | I30: =I42*I11 -> 6.7286108 | J30: =J42*J11 -> 6.8968261
B32: Accounts Payable | C32: =14.45*1.16 -> 16.762 | D32: =9.93*1.16 -> 11.5188 | E32: =10.34*1.16 -> 11.9944 | F32: =F43*F11 -> 10.505928 | G32: =G43*G11 -> 10.768576 | H32: =H43*H11 -> 11.037791 | I32: =I43*I11 -> 11.313736 | J32: =J43*J11 -> 11.596579
B33: Accrued Expenses | C33: =12.93*1.16 -> 14.9988 | D33: =12.49*0.16 -> 1.9984 | E33: =13.45*1.16 -> 15.602 | F33: =F44*F11 -> 9.136712 | G33: =G44*G11 -> 9.3651298 | H33: =H44*H11 -> 9.5992581 | I33: =I44*I11 -> 9.8392395 | J33: =J44*J11 -> 10.08522
B35: Debt | C35: =35.7*1.16 -> 41.412 | D35: =30.56*1.16 -> 35.4496 | E35: =30.81*1.16 -> 35.7396
C36: =3.89*1.16 -> 4.5124 | D36: =5.02*1.16 -> 5.8232 | E36: =5*1.16 -> 5.8
B38: Gross PP&E (Increases annually be capex) | C38: =77.34*1.16 -> 89.7144 | D38: =53.06*1.16 -> 61.5496 | E38: =41.44*1.16 -> 48.0704
B40: Accounts Recevable % of revenue | C40: =C28/C11 -> 0.046437703 | D40: =D28/D11 -> 0.030880993 | E40: =E28/E11 -> 0.030348837 | F40: =AVERAGE($C$40:$E$40) -> 0.035889178 | G40: =AVERAGE($C$40:$E$40) -> 0.035889178 | H40: =AVERAGE($C$40:$E$40) -> 0.035889178 | I40: =AVERAGE($C$40:$E$40) -> 0.035889178 | J40: =AVERAGE($C$40:$E$40) -> 0.035889178
B41: Inventories % of revenue | C41: =C29/C11 -> 0.3031961 | D41: =D29/D11 -> 0.21695206 | E41: =E29/E11 -> 0.17554153 | F41: =AVERAGE($C$41:$E$41) -> 0.23189656 | G41: =AVERAGE($C$41:$E$41) -> 0.23189656 | H41: =AVERAGE($C$41:$E$41) -> 0.23189656 | I41: =AVERAGE($C$41:$E$41) -> 0.23189656 | J41: =AVERAGE($C$41:$E$41) -> 0.23189656
B42: Prepaid Expenses % of revenue | C42: =C30/C11 -> 0.044489707 | D42: =D30/D11 -> 0.047760857 | E42: =E30/E11 -> 0.059637874 | F42: =AVERAGE($C$42:$E$42) -> 0.05062948 | G42: =AVERAGE($C$42:$E$42) -> 0.05062948 | H42: =AVERAGE($C$42:$E$42) -> 0.05062948 | I42: =AVERAGE($C$42:$E$42) -> 0.05062948 | J42: =AVERAGE($C$42:$E$42) -> 0.05062948
B43: Accounts Payable % of revenue | C43: =C32/C11 -> 0.090801733 | D43: =D32/D11 -> 0.064967851 | E43: =E32/E11 -> 0.099621262 | F43: =AVERAGE($C$43:$E$43) -> 0.085130282 | G43: =AVERAGE($C$43:$E$43) -> 0.085130282 | H43: =AVERAGE($C$43:$E$43) -> 0.085130282 | I43: =AVERAGE($C$43:$E$43) -> 0.085130282 | J43: =AVERAGE($C$43:$E$43) -> 0.085130282
B44: Accrued Expenses % of revenue | C44: =C33/C11 -> 0.081250271 | D44: =D33/D11 -> 0.011271292 | E44: =E33/E11 -> 0.12958472 | F44: =AVERAGE($C$44:$E$44) -> 0.074035427 | G44: =AVERAGE($C$44:$E$44) -> 0.074035427 | H44: =AVERAGE($C$44:$E$44) -> 0.074035427 | I44: =AVERAGE($C$44:$E$44) -> 0.074035427 | J44: =AVERAGE($C$44:$E$44) -> 0.074035427
B45: Capital Expenditures % of revenue | C45: =C89/C11 -> -0.038624052 | D45: =D89/D11 -> -0.03355894 | E45: =E89/E11 -> -0.009551495 | F45: =AVERAGE($C$45:$E$45) -> -0.027244829 | G45: =AVERAGE($C$45:$E$45) -> -0.027244829 | H45: =AVERAGE($C$45:$E$45) -> -0.027244829 | I45: =AVERAGE($C$45:$E$45) -> -0.027244829 | J45: =AVERAGE($C$45:$E$45) -> -0.027244829
B52: WACC
B53: Share Price | D53: =C5 -> 1.596
B54: Dilueted Shares Outstanding | D54: =C6 -> 70.16
B55: Cost of debt | D55: =AVERAGE(C36:E36)/AVERAGE(C35:E35) -> 0.14329865
B56: Tax rate | D56: 0.25
B57: After tax cost of debt | D57: =D55*(1-D56) -> 0.10747399
B58: Beta Levered | D58: =0.74*(1+(1-D56)*(D61/D62)) -> 0.92603398
...

Sheet Target Recommendation
B2: Moncler S.p.A (BIT: MONC) - Target Recommendation
B3: Summary Recap (€mm)
B4: Company | C4: Equity DCF Value | D4: Market Price | E4: Target Price | F4: Upside/Downside | G4: Outcome
B5: Ferragamo | C5: ='DCF - Ferragamo'!C96 -> 1720.5737 | D5: ='DCF - Ferragamo'!C5 -> 10.27 | E5: ='DCF - Ferragamo'!C98 -> 10.384921 | F5: =E5/D5-1 -> 0.011189955 | G5: Recommend
B6: Burberry | C6: ='DCF - Burberry'!C96 -> 6214.9092 | D6: ='DCF - Burberry'!C5 -> 12.6768 | E6: ='DCF - Burberry'!C98 -> 17.349904 | F6: =E6/D6-1 -> 0.36863438 | G6: Not Recommend
B7: Mulberry | C7: ='DCF - Mulberry Group plc'!C106 -> 117.08315 | D7: ='DCF - Mulberry Group plc'!C5 -> 1.596 | E7: ='DCF - Mulberry Group plc'!C108 -> 1.6688021 | F7: =E7/D7-1 -> 0.045615344 | G7: Not Recommend
B8: Exclusion Rationally
B9: Company | C9: Rational | E9: Investment Thesis
B10: Burberry Group plc | C10: Despite a DCF upside of 36.86%, Burberry is excluded due to its total equity value of €6.2B, which would require Moncler to undertake significant debt financing to complete the acquisition | E10: Ferragamo operates primarily in the luxury leather goods segment, a category with limited seasonality exposure. An acquisition would allow Moncler to diversify its revenue base beyond outerwear. Ferragamo S.p.A is the best target thanks to an Enterprise Value that is less than the Enterprise Value of Moncler, the management is available to sell and the company has an important brand on the leather goods segment. The DCF model shows that Ferragamo operate at fair value, so the premium for the acquisition could be less than the other companies. However Ferragamo is undergoing a strategic positioning under new management, with revenue stabilizing and Margin expected to recover to the historical levels. This creates an acquisition opportunity, as the current valuation does not yet fully reflect the potential of the ongoing operational turnaround. Key risk remains the execution of the ongoing repositioning strategy, which Moncler can mitigate through its operational expertise in luxury brand management.
B11: Mulberry Group plc | C11: Mulberry, despite the feasibility of the acquisition, because the management want to sell and the value of the company does not require a significant debt operation for Moncler, is excluded due to the low margins and because the brand does not meet Moncler's brand equity standard.
B12: Recommended Target
B13: Company | C13: Minimum Premium | D13: Maximum premium | E13: Minimum Price per Share | F13: Maximum Price per Share | G13: Minimum total price | H13: Maximum total price
B14: Salvatore Ferragamo S.p.A. | C14: 0.2 | D14: 0.35 | E14: ='DCF - Ferragamo'!C5*(1+'Target Recommendation'!C14) -> 12.324 | F14: ='DCF - Ferragamo'!C5*(1+'Target Recommendation'!D14) -> 13.8645 | G14: =E14*'DCF - Ferragamo'!$C$97 -> 2041.8403 | H14: =F14*'DCF - Ferragamo'!$C$97 -> 2297.0704

Sheet Target Due Diligence
B2: Salvatore Ferragamo S.p.A. - Due Diligence
B4: Area | C4: Key Finding | D4: Supporting Data | E4: Risk Level
B5: Quality of Earnings | C5: Operating cost base was misaligned with declining revenues in FY2024 (distribution costs +10% vs. revenue -10%), followed by an aggressive cost-cutting program in FY2025 (-14%) under new management, indicating an active but still unproven turnaround. | D5: Sales & distribution costs: €454.6M (FY2023) → €496.5M (FY2024, +9.2%) → €427.3M (FY2025, -13.9%) | E5: Medium
B6: Working Capital Analysis | C6: Inventories as % of revenue increased and remained elevated despite declining sales, signaling slower inventory turnover. This creates risk of future markdown activity to clear aged stock, with potential negative impact on gross margin rather than top-line revenue. | D6: Inventories as % of revenue: 25,81% (FY2023) → 29,75% (FY2024) → 28,53% (FY2025) | E6: Medium - High
B7: Net Debt Analysis | C7: Group faces routine tax/customs audits in Japan (concluded, ~€958K paid), South Korea (ongoing, transfer pricing review) and France (ongoing, FY2021-2024). Management assesses risk of unfavorable outcome as 'no more than possible' — standard multinational tax exposure, not a material transaction risk. | D7: Note 23 and note 52 | E7: Low
B8: Capex normalized | C8: Capex declined 35% YoY (FY2024-FY2025) against a 5.7% revenue decline, suggesting investment cuts beyond what revenue contraction alone would justify. Annual report does not disclose capex breakdown by category (store renovation, IT, logistics), limiting visibility into whether reductions affect maintenance or growth investments. Risk of underinvestment in retail network requires further due diligence access to internal capex planning. | D8: Capex: €61.3M (FY2024) → €39.6M (FY2025), -35.4%. Revenue: -5.7% over same period. | E8: Medium
B9: Tax Analysis | C9: Group benefits from Advance Pricing Agreements with Italian and US tax authorities (effective through 2026/2028), reducing transfer pricing risk. Losses appear concentrated in operating subsidiaries rather than the Italian parent company, which remains profitable at standalone level — consistent with the geographic/retail-level nature of the operational downturn identified in the Quality of Earnings analysis. | D9: Note 41 | E9: Low

Sheet Sources & Uses
B2: Moncler S.p.A. - Sources & Uses
B4: Sources (€mm) | D4: Uses (€mm)
B5: Cash | C5: 500 | D5: Purchase of equity | E5: =12.5*'DCF - Ferragamo'!C97 -> 2071
B6: New Debt | C6: =E8-C5 -> 1612.42 | D6: Refinancing of existing debt | E6: 0
D7: Transaction fees | E7: =E5*2% -> 41.42
B8: Total Sources | C8: =SUM(C5:C6) -> 2112.42 | D8: Total Uses | E8: =SUM(E5:E7) -> 2112.42
B11: Cash funding assumes Moncler retains a minimum operating cash reserve of approximately €726M (€1,226M gross cash less €500M deployed), consistent with working capital and liquidity needs of a luxury group of this scale. | D11: Existing Ferragamo debt (€104M) assumed to remain outstanding post-acquisition, not refinanced at closing, given its modest size and favorable terms relative to potential new financing costs.

Sheet Synergies
B2: Moncler S.p.A. - Synergies
B4: Base Data | C4: Moncler | D4: Ferragamo
B5: COGS | C5: 685.93 | D5: 311.53
B6: G&A | C6: 357.43 | D6: 124.81
B8: Synergy Type | C8: Base | D8: % Applied | E8: Annual Value | F8: Rationale
B9: G&A Overlap | C9: =SUM(C6:D6) -> 482.24 | D9: 0.03 | E9: =C9*D9 -> 14.4672 | F9: Elimination of duplicate corporate funcionts
B10: Procurement | C10: =SUM(C5:D5) -> 997.46 | D10: 0.015 | E10: =C10*D10 -> 14.9619 | F10: Combined purchasing power with shared italian suppliers
B11: Total | E11: =SUM(E9,E10) -> 29.4291
B13: Revenue synergies not quantified due to high execution uncertainty. Potential upside from cross-selling through combined retail network not included in base case.
B14: Synergies assumed to be fully realized by Year 3, with 33% realization in Year 1, 67% in Year 2, and 100% from Year 3 onwards.

Sheet Accretion or Dilution
B2: Moncler S.p.A. - Accretion or Dilution model
B5: Standalone Moncler Net Income | C5: 626.67
B6: (+) Ferragamo Net Income | C6: -49.43
B7: (+) Annual Synegies after tax | C7: =Synergies!E11*(1-0.24) -> 22.366116
B8: (-) After Tax Lost Interest Income | C8: =-('Sources & Uses'!C5*2.4%*(1-24%)) -> -9.12
B9: (-) After Tax Interest Cost | C9: =-('Sources & Uses'!C6*'DCF - Ferragamo'!D52) -> -49.133175
B10: Pro Forma Combined Net Income | C10: =SUM(C5:C8) -> 590.48612
B11: (/) Shares Outstanding Moncler | C11: 271.6
B12: Pro Forma EPS | C12: =C10/C11 -> 2.174102
B13: Standalone EPS | C13: =C5/'Accretion or Dilution'!C11 -> 2.307327
B14: Accretion/(Dilution) | C14: =(C12/C13)-1 -> -0.057739933
B17: The acquisition is expected to be dilutive in Year 1 (-5.77%) due to Ferragamo's ongoing operational turnaround and current negative net income. However, accretion is expected from Year 3 onwards as Ferragamo's margins recover toward historical levels and cost synergies of €29.4M per annum materialize fully. Management's decision to proceed would be contingent on the long-term strategic value of the acquisition exceeding the short-term EPS dilution.
